Workbook

Sheet Main
B1: TENX | E1: TENAX THERAPEUTICS — CLINICAL TRIAL ANALYSIS
B2: Main | E2: TNX-103 LEVEL - Risk-Adjusted Valuation & Simulation Analysis
B4: MARKET SNAPSHOT | E4: DCF VALUATION (RISK-ADJUSTED) | H4: TRIAL SIMULATION RESULTS
B5: Stock Price | C5: 12.25 | E5: Risk-Adj. NPV (RNPV) | F5: $320M | H5: 6MWD (Normal, n=1000)
B6: Shares Outstanding (M) | C6: 45.226328 | E6: Peak Revenue | F6: $742M | H6: Avg Mean Δ6MWD (m) | I6: ='Base Case (Normal)'!G7 -> 39.097525
B7: Market Cap ($M) | C7: =C5*C6 -> 554.02252 | E7: Peak FCF | F7: $182M | H7: 95% CI Low (m) | I7: ='Base Case (Normal)'!G8 -> -59.440546
B8: Cash ($M) | C8: 118.755 | E8: Breakeven Year | F8: 2033 | H8: 95% CI High (m) | I8: ='Base Case (Normal)'!G9 -> 132.02071
B9: Debt ($M) | C9: 0 | E9: WACC | F9: =DCF!E5 -> 0.12 | H9: Probability of Success | I9: ='Base Case (Normal)'!G10 -> 0.621
B10: Enterprise Value ($M) | C10: =C7-C8+C9 -> 435.26752 | E10: Probability of Success (Monte Carlo) | F10: =+'Conservative Case (Monte Carlo)'!Q25 -> 0.51717172 | H10: 6MWD (With Phase 2 Info)
B11: Source: Q1 2026 | E11: See: DCF sheet / Monte Carlo Sheet | H11: Probability of Success | I11: ='Bull Case (Phase 2 Prior)'!G10 -> 0.666
H12: 95% CI Low (m) | I12: ='Bull Case (Phase 2 Prior)'!G8 -> -14.620282
B13: MONTE CARLO — TWO-SCENARIO ANALYSIS
B14: Scenario | C14: PoS | E14: Description | H14: Key Parameter | I14: Value
B15: S1: Two-Arm Trial (Phase 2 Priors) | C15: ='Conservative Case (Monte Carlo)'!Q17 -> 0.53737374 | E15: Standard two-arm trial using Phase 2 priors as treatment mean distribution | H15: Exp. Stock Move (S1) | I15: ='Conservative Case (Monte Carlo)'!Q18 -> 4.2079
B16: S2: Bayesian-Updated Posterior | C16: ='Conservative Case (Monte Carlo)'!Q25 -> 0.51717172 | E16: Bayesian posterior blends Phase 2 data with mechanistic prior for updated PoS | H16: Exp. Stock Move (S2) | I16: ='Conservative Case (Monte Carlo)'!Q26 -> 3.6254

Sheet Conservative Case (Monte Carlo)
A1: TENX — Monte Carlo Simulation
A2: Conservative Case | σ=60m, Mean=30m, dual gate (p<0.05 AND Δ≥25m) | S1 PoS ~58% / S2 ~51%
A6: SIMULATION PARAMETERS (Mean: 20m) | B6: 30 | D6: OUTCOME KEY | K6: BAYESIAN INPUTS | R6: Outcome | S6: Count
A7: Patient-Level SD σ (m) | B7: 60 | D7: Outcome | E7: Stock Move | L7: Phase 2 Mean Δ6MWD | M7: μₚ | N7: 25 | R7: Fail | S7: =COUNTIF(K16:K1005,R7) -> 478
A8: Placebo Mean (m) | B8: 5 | D8: Fail | E8: -0.95 | L8: Phase 2 SD | M8: σₚ | N8: 18 | R8: Marginal | S8: =COUNTIF(K16:K1005,R8) -> 91
A9: Sample Size (per arm) | B9: 115 | D9: Marginal | E9: 3 | L9: Mechanistic Confidence | M9: M | N9: 0.7 | R9: Solid | S9: =COUNTIF(K16:K1005,R9) -> 182
A10: Significance Threshold | B10: 0.05 | D10: Solid | E10: 5 | L10: Prior Weight Base | M10: w₀ | N10: 0.55 | R10: Blowout | S10: =COUNTIF(K16:K1005,R10) -> 239
A11: Success Threshold (m) | B11: 20 | D11: Blowout | E11: 12.5 | L11: Effective Prior Weight (w = w₀×M) | M11: w | N11: =N9*N10 -> 0.385
A12: Effect Uncertainty σ (m) | B12: 20 | L12: SE of mean difference = | M12: =$B$7*SQRT(2/$B$9) -> 7.9125657
A14: SCENARIO 1: TWO-ARM TRIAL (PHASE 2 PRIORS) | F14: SCENARIO 2: BAYESIAN-UPDATED POSTERIOR
A15: Trt Mean Δ16MWD | B15: Pbo Mean Δ16MWD | C15: Observed Δ (Trt−Pbo) | D15: t-stat | E15: p-value | F15: Posterior Δ16MWD | G15: Obs Δ (Posterior) | H15: t-stat (Post) | I15: p-value (Post) | J15: S2 Success | K15: S2 Outcome | L15: S1 Success | M15: S1 Outcome | P15: SIMULATION OUTPUT
A16: =NORMINV(RAND(), MAX(0, NORMINV(RAND(), $B$6, $B$12)), $B$7/SQRT($B$9)) -> 27.532442 | B16: =NORMINV(RAND(), $B$8, $B$7/SQRT($B$9)) -> -2.4436015 | C16: =A16-B16 -> 29.976043 | D16: =C16/($B$7*SQRT(2/$B$9)) -> 3.78841 | E16: =_xlfn.T.DIST.RT(D16, 2*$B$9-2) -> 9.7011158e-05 | F16: =NORMINV(RAND(), MAX(0, NORMINV(RAND(), $N$7, $N$8)), $B$7/SQRT($B$9)) -> 4.0243806 | G16: =F16-B16 -> 6.4679822 | H16: =G16/($B$7*SQRT(2/$B$9)) -> 0.81743172 | I16: =_xlfn.T.DIST.RT(H16, 2*$B$9-2) -> 0.20726756 | J16: =IF(AND(I16<$B$10, G16>=$B$11), 1, 0) -> 0 | K16: {=_xlfn.IFS(G16<$B$11,"Fail",G16<25,"Marginal",G16<35,"Solid",TRUE,"Blowout")} -> Fail | L16: =IF(AND(E16<$B$10,C16>=$B$11),1,0) -> 1 | M16: {=_xlfn.IFS(C16<$B$11,"Fail",C16<25,"Marginal",C16<35,"Solid",TRUE,"Blowout")} -> Solid | P16: SCENARIO 1 (t-test)
A17: =NORMINV(RAND(), MAX(0, NORMINV(RAND(), $B$6, $B$12)), $B$7/SQRT($B$9)) -> 50.875364 | B17: =NORMINV(RAND(), $B$8, $B$7/SQRT($B$9)) -> 8.5889767 | C17: =A17-B17 -> 42.286387 | D17: =C17/($B$7*SQRT(2/$B$9)) -> 5.3442068 | E17: =_xlfn.T.DIST.RT(D17, 2*$B$9-2) -> 1.0993829e-07 | F17: =NORMINV(RAND(), MAX(0, NORMINV(RAND(), $N$7, $N$8)), $B$7/SQRT($B$9)) -> 22.10723 | G17: =F17-B17 -> 13.518253 | H17: =G17/($B$7*SQRT(2/$B$9)) -> 1.7084538 | I17: =_xlfn.T.DIST.RT(H17, 2*$B$9-2) -> 0.044456543 | J17: =IF(AND(I17<$B$10, G17>=$B$11), 1, 0) -> 0 | K17: {=_xlfn.IFS(G17<$B$11,"Fail",G17<25,"Marginal",G17<35,"Solid",TRUE,"Blowout")} -> Fail | L17: =IF(AND(E17<$B$10,C17>=$B$11),1,0) -> 1 | M17: {=_xlfn.IFS(C17<$B$11,"Fail",C17<25,"Marginal",C17<35,"Solid",TRUE,"Blowout")} -> Blowout | P17: Prob of Success | Q17: =AVERAGE(L16:L1005) -> 0.53737374
A18: =NORMINV(RAND(), MAX(0, NORMINV(RAND(), $B$6, $B$12)), $B$7/SQRT($B$9)) -> 30.238795 | B18: =NORMINV(RAND(), $B$8, $B$7/SQRT($B$9)) -> 10.508494 | C18: =A18-B18 -> 19.730301 | D18: =C18/($B$7*SQRT(2/$B$9)) -> 2.4935403 | E18: =_xlfn.T.DIST.RT(D18, 2*$B$9-2) -> 0.0066790172 | F18: =NORMINV(RAND(), MAX(0, NORMINV(RAND(), $N$7, $N$8)), $B$7/SQRT($B$9)) -> 4.4546677 | G18: =F18-B18 -> -6.0538258 | H18: =G18/($B$7*SQRT(2/$B$9)) -> -0.76509012 | I18: =_xlfn.T.DIST.RT(H18, 2*$B$9-2) -> 0.77749546 | J18: =IF(AND(I18<$B$10, G18>=$B$11), 1, 0) -> 0 | K18: {=_xlfn.IFS(G18<$B$11,"Fail",G18<25,"Marginal",G18<35,"Solid",TRUE,"Blowout")} -> Fail | L18: =IF(AND(E18<$B$10,C18>=$B$11),1,0) -> 0 | M18: {=_xlfn.IFS(C18<$B$11,"Fail",C18<25,"Marginal",C18<35,"Solid",TRUE,"Blowout")} -> Fail | P18: Exp Stock Move | Q18: =COUNTIF(M16:M1005,"Fail")/1000*-0.95+COUNTIF(M16:M1005,"Marginal")/1000*2+COUNTIF(M16:M1005,"Solid")/1000*5+COUNTIF(M16:M1005,"Blowout")/1000*12.5 -> 4.2079
A19: =NORMINV(RAND(), MAX(0, NORMINV(RAND(), $B$6, $B$12)), $B$7/SQRT($B$9)) -> -0.63445564 | B19: =NORMINV(RAND(), $B$8, $B$7/SQRT($B$9)) -> -2.0057027 | C19: =A19-B19 -> 1.371247 | D19: =C19/($B$7*SQRT(2/$B$9)) -> 0.17329993 | E19: =_xlfn.T.DIST.RT(D19, 2*$B$9-2) -> 0.43128472 | F19: =NORMINV(RAND(), MAX(0, NORMINV(RAND(), $N$7, $N$8)), $B$7/SQRT($B$9)) -> 17.865469 | G19: =F19-B19 -> 19.871172 | H19: =G19/($B$7*SQRT(2/$B$9)) -> 2.5113436 | I19: =_xlfn.T.DIST.RT(H19, 2*$B$9-2) -> 0.006360159 | J19: =IF(AND(I19<$B$10, G19>=$B$11), 1, 0) -> 0 | K19: {=_xlfn.IFS(G19<$B$11,"Fail",G19<25,"Marginal",G19<35,"Solid",TRUE,"Blowout")} -> Fail | L19: =IF(AND(E19<$B$10,C19>=$B$11),1,0) -> 0 | M19: {=_xlfn.IFS(C19<$B$11,"Fail",C19<25,"Marginal",C19<35,"Solid",TRUE,"Blowout")} -> Fail | P19: Fail | Q19: =COUNTIF(M16:M1005,"Fail")/1000 -> 0.458
A20: =NORMINV(RAND(), MAX(0, NORMINV(RAND(), $B$6, $B$12)), $B$7/SQRT($B$9)) -> 39.171648 | B20: =NORMINV(RAND(), $B$8, $B$7/SQRT($B$9)) -> -2.2648275 | C20: =A20-B20 -> 41.436476 | D20: =C20/($B$7*SQRT(2/$B$9)) -> 5.2367939 | E20: =_xlfn.T.DIST.RT(D20, 2*$B$9-2) -> 1.8547075e-07 | F20: =NORMINV(RAND(), MAX(0, NORMINV(RAND(), $N$7, $N$8)), $B$7/SQRT($B$9)) -> 42.213229 | G20: =F20-B20 -> 44.478057 | H20: =G20/($B$7*SQRT(2/$B$9)) -> 5.6211928 | I20: =_xlfn.T.DIST.RT(H20, 2*$B$9-2) -> 2.7564134e-08 | J20: =IF(AND(I20<$B$10, G20>=$B$11), 1, 0) -> 1 | K20: {=_xlfn.IFS(G20<$B$11,"Fail",G20<25,"Marginal",G20<35,"Solid",TRUE,"Blowout")} -> Blowout | L20: =IF(AND(E20<$B$10,C20>=$B$11),1,0) -> 1 | M20: {=_xlfn.IFS(C20<$B$11,"Fail",C20<25,"Marginal",C20<35,"Solid",TRUE,"Blowout")} -> Blowout | P20: Marginal | Q20: =COUNTIF(M16:M1005,"Marginal")/1000 -> 0.079
A21: =NORMINV(RAND(), MAX(0, NORMINV(RAND(), $B$6, $B$12)), $B$7/SQRT($B$9)) -> 33.431063 | B21: =NORMINV(RAND(), $B$8, $B$7/SQRT($B$9)) -> 5.9808569 | C21: =A21-B21 -> 27.450206 | D21: =C21/($B$7*SQRT(2/$B$9)) -> 3.4691916 | E21: =_xlfn.T.DIST.RT(D21, 2*$B$9-2) -> 0.00031202848 | F21: =NORMINV(RAND(), MAX(0, NORMINV(RAND(), $N$7, $N$8)), $B$7/SQRT($B$9)) -> 10.144417 | G21: =F21-B21 -> 4.1635606 | H21: =G21/($B$7*SQRT(2/$B$9)) -> 0.52619602 | I21: =_xlfn.T.DIST.RT(H21, 2*$B$9-2) -> 0.29963174 | J21: =IF(AND(I21<$B$10, G21>=$B$11), 1, 0) -> 0 | K21: {=_xlfn.IFS(G21<$B$11,"Fail",G21<25,"Marginal",G21<35,"Solid",TRUE,"Blowout")} -> Fail | L21: =IF(AND(E21<$B$10,C21>=$B$11),1,0) -> 1 | M21: {=_xlfn.IFS(C21<$B$11,"Fail",C21<25,"Marginal",C21<35,"Solid",TRUE,"Blowout")} -> Solid | P21: Solid | Q21: =COUNTIF(M16:M1005,"Solid")/1000 -> 0.157
A22: =NORMINV(RAND(), MAX(0, NORMINV(RAND(), $B$6, $B$12)), $B$7/SQRT($B$9)) -> 7.5162054 | B22: =NORMINV(RAND(), $B$8, $B$7/SQRT($B$9)) -> -11.95437 | C22: =A22-B22 -> 19.470575 | D22: =C22/($B$7*SQRT(2/$B$9)) -> 2.4607158 | E22: =_xlfn.T.DIST.RT(D22, 2*$B$9-2) -> 0.007304371 | F22: =NORMINV(RAND(), MAX(0, NORMINV(RAND(), $N$7, $N$8)), $B$7/SQRT($B$9)) -> 43.479868 | G22: =F22-B22 -> 55.434237 | H22: =G22/($B$7*SQRT(2/$B$9)) -> 7.0058486 | I22: =_xlfn.T.DIST.RT(H22, 2*$B$9-2) -> 1.3682926e-11 | J22: =IF(AND(I22<$B$10, G22>=$B$11), 1, 0) -> 1 | K22: {=_xlfn.IFS(G22<$B$11,"Fail",G22<25,"Marginal",G22<35,"Solid",TRUE,"Blowout")} -> Blowout | L22: =IF(AND(E22<$B$10,C22>=$B$11),1,0) -> 0 | M22: {=_xlfn.IFS(C22<$B$11,"Fail",C22<25,"Marginal",C22<35,"Solid",TRUE,"Blowout")} -> Fail | P22: Blowout | Q22: =COUNTIF(M16:M1005,"Blowout")/1000 -> 0.296
A23: =NORMINV(RAND(), MAX(0, NORMINV(RAND(), $B$6, $B$12)), $B$7/SQRT($B$9)) -> 47.775396 | B23: =NORMINV(RAND(), $B$8, $B$7/SQRT($B$9)) -> 8.4852334 | C23: =A23-B23 -> 39.290163 | D23: =C23/($B$7*SQRT(2/$B$9)) -> 4.9655402 | E23: =_xlfn.T.DIST.RT(D23, 2*$B$9-2) -> 6.712047e-07 | F23: =NORMINV(RAND(), MAX(0, NORMINV(RAND(), $N$7, $N$8)), $B$7/SQRT($B$9)) -> 17.049479 | G23: =F23-B23 -> 8.5642456 | H23: =G23/($B$7*SQRT(2/$B$9)) -> 1.0823601 | I23: =_xlfn.T.DIST.RT(H23, 2*$B$9-2) -> 0.14011796 | J23: =IF(AND(I23<$B$10, G23>=$B$11), 1, 0) -> 0 | K23: {=_xlfn.IFS(G23<$B$11,"Fail",G23<25,"Marginal",G23<35,"Solid",TRUE,"Blowout")} -> Fail | L23: =IF(AND(E23<$B$10,C23>=$B$11),1,0) -> 1 | M23: {=_xlfn.IFS(C23<$B$11,"Fail",C23<25,"Marginal",C23<35,"Solid",TRUE,"Blowout")} -> Blowout
A24: =NORMINV(RAND(), MAX(0, NORMINV(RAND(), $B$6, $B$12)), $B$7/SQRT($B$9)) -> 34.616218 | B24: =NORMINV(RAND(), $B$8, $B$7/SQRT($B$9)) -> 8.3709903 | C24: =A24-B24 -> 26.245228 | D24: =C24/($B$7*SQRT(2/$B$9)) -> 3.3169049 | E24: =_xlfn.T.DIST.RT(D24, 2*$B$9-2) -> 0.00052957056 | F24: =NORMINV(RAND(), MAX(0, NORMINV(RAND(), $N$7, $N$8)), $B$7/SQRT($B$9)) -> 24.582884 | G24: =F24-B24 -> 16.211894 | H24: =G24/($B$7*SQRT(2/$B$9)) -> 2.0488795 | I24: =_xlfn.T.DIST.RT(H24, 2*$B$9-2) -> 0.020809503 | J24: =IF(AND(I24<$B$10, G24>=$B$11), 1, 0) -> 0 | K24: {=_xlfn.IFS(G24<$B$11,"Fail",G24<25,"Marginal",G24<35,"Solid",TRUE,"Blowout")} -> Fail | L24: =IF(AND(E24<$B$10,C24>=$B$11),1,0) -> 1 | M24: {=_xlfn.IFS(C24<$B$11,"Fail",C24<25,"Marginal",C24<35,"Solid",TRUE,"Blowout")} -> Solid | P24: SCENARIO 2: BAYESIAN
A25: =NORMINV(RAND(), MAX(0, NORMINV(RAND(), $B$6, $B$12)), $B$7/SQRT($B$9)) -> 40.329006 | B25: =NORMINV(RAND(), $B$8, $B$7/SQRT($B$9)) -> 6.3710184 | C25: =A25-B25 -> 33.957988 | D25: =C25/($B$7*SQRT(2/$B$9)) -> 4.2916532 | E25: =_xlfn.T.DIST.RT(D25, 2*$B$9-2) -> 1.3112125e-05 | F25: =NORMINV(RAND(), MAX(0, NORMINV(RAND(), $N$7, $N$8)), $B$7/SQRT($B$9)) -> 17.221051 | G25: =F25-B25 -> 10.850032 | H25: =G25/($B$7*SQRT(2/$B$9)) -> 1.3712407 | I25: =_xlfn.T.DIST.RT(H25, 2*$B$9-2) -> 0.085824007 | J25: =IF(AND(I25<$B$10, G25>=$B$11), 1, 0) -> 0 | K25: {=_xlfn.IFS(G25<$B$11,"Fail",G25<25,"Marginal",G25<35,"Solid",TRUE,"Blowout")} -> Fail | L25: =IF(AND(E25<$B$10,C25>=$B$11),1,0) -> 1 | M25: {=_xlfn.IFS(C25<$B$11,"Fail",C25<25,"Marginal",C25<35,"Solid",TRUE,"Blowout")} -> Solid | P25: Prob of Success | Q25: =AVERAGE(J16:J1005) -> 0.51717172
A26: =NORMINV(RAND(), MAX(0, NORMINV(RAND(), $B$6, $B$12)), $B$7/SQRT($B$9)) -> 10.725795 | B26: =NORMINV(RAND(), $B$8, $B$7/SQRT($B$9)) -> 10.628719 | C26: =A26-B26 -> 0.097076078 | D26: =C26/($B$7*SQRT(2/$B$9)) -> 0.012268597 | E26: =_xlfn.T.DIST.RT(D26, 2*$B$9-2) -> 0.49511102 | F26: =NORMINV(RAND(), MAX(0, NORMINV(RAND(), $N$7, $N$8)), $B$7/SQRT($B$9)) -> 44.111553 | G26: =F26-B26 -> 33.482834 | H26: =G26/($B$7*SQRT(2/$B$9)) -> 4.2316026 | I26: =_xlfn.T.DIST.RT(H26, 2*$B$9-2) -> 1.6816927e-05 | J26: =IF(AND(I26<$B$10, G26>=$B$11), 1, 0) -> 1 | K26: {=_xlfn.IFS(G26<$B$11,"Fail",G26<25,"Marginal",G26<35,"Solid",TRUE,"Blowout")} -> Solid | L26: =IF(AND(E26<$B$10,C26>=$B$11),1,0) -> 0 | M26: {=_xlfn.IFS(C26<$B$11,"Fail",C26<25,"Marginal",C26<35,"Solid",TRUE,"Blowout")} -> Fail | P26: Exp Stock Move | Q26: =COUNTIF(K16:K1005,"Fail")/1000*-0.95+COUNTIF(K16:K1005,"Marginal")/1000*2+COUNTIF(K16:K1005,"Solid")/1000*5+COUNTIF(K16:K1005,"Blowout")/1000*12.5 -> 3.6254
A27: =NORMINV(RAND(), MAX(0, NORMINV(RAND(), $B$6, $B$12)), $B$7/SQRT($B$9)) -> 13.770159 | B27: =NORMINV(RAND(), $B$8, $B$7/SQRT($B$9)) -> 11.44743 | C27: =A27-B27 -> 2.3227289 | D27: =C27/($B$7*SQRT(2/$B$9)) -> 0.29354939 | E27: =_xlfn.T.DIST.RT(D27, 2*$B$9-2) -> 0.38468464 | F27: =NORMINV(RAND(), MAX(0, NORMINV(RAND(), $N$7, $N$8)), $B$7/SQRT($B$9)) -> 2.4025091 | G27: =F27-B27 -> -9.044921 | H27: =G27/($B$7*SQRT(2/$B$9)) -> -1.1431085 | I27: =_xlfn.T.DIST.RT(H27, 2*$B$9-2) -> 0.8729038 | J27: =IF(AND(I27<$B$10, G27>=$B$11), 1, 0) -> 0 | K27: {=_xlfn.IFS(G27<$B$11,"Fail",G27<25,"Marginal",G27<35,"Solid",TRUE,"Blowout")} -> Fail | L27: =IF(AND(E27<$B$10,C27>=$B$11),1,0) -> 0 | M27: {=_xlfn.IFS(C27<$B$11,"Fail",C27<25,"Marginal",C27<35,"Solid",TRUE,"Blowout")} -> Fail | P27: Fail | Q27: =COUNTIF(K16:K1005,"Fail")/1000 -> 0.478
A28: =NORMINV(RAND(), MAX(0, NORMINV(RAND(), $B$6, $B$12)), $B$7/SQRT($B$9)) -> 26.70462 | B28: =NORMINV(RAND(), $B$8, $B$7/SQRT($B$9)) -> 11.133137 | C28: =A28-B28 -> 15.571482 | D28: =C28/($B$7*SQRT(2/$B$9)) -> 1.9679435 | E28: =_xlfn.T.DIST.RT(D28, 2*$B$9-2) -> 0.025143292 | F28: =NORMINV(RAND(), MAX(0, NORMINV(RAND(), $N$7, $N$8)), $B$7/SQRT($B$9)) -> 13.689664 | G28: =F28-B28 -> 2.5565268 | H28: =G28/($B$7*SQRT(2/$B$9)) -> 0.32309708 | I28: =_xlfn.T.DIST.RT(H28, 2*$B$9-2) -> 0.37345892 | J28: =IF(AND(I28<$B$10, G28>=$B$11), 1, 0) -> 0 | K28: {=_xlfn.IFS(G28<$B$11,"Fail",G28<25,"Marginal",G28<35,"Solid",TRUE,"Blowout")} -> Fail | L28: =IF(AND(E28<$B$10,C28>=$B$11),1,0) -> 0 | M28: {=_xlfn.IFS(C28<$B$11,"Fail",C28<25,"Marginal",C28<35,"Solid",TRUE,"Blowout")} -> Fail | P28: Marginal | Q28: =COUNTIF(K16:K1005,"Marginal")/1000 -> 0.091
A29: =NORMINV(RAND(), MAX(0, NORMINV(RAND(), $B$6, $B$12)), $B$7/SQRT($B$9)) -> 26.861149 | B29: =NORMINV(RAND(), $B$8, $B$7/SQRT($B$9)) -> 7.0990587 | C29: =A29-B29 -> 19.762091 | D29: =C29/($B$7*SQRT(2/$B$9)) -> 2.4975579 | E29: =_xlfn.T.DIST.RT(D29, 2*$B$9-2) -> 0.0066058447 | F29: =NORMINV(RAND(), MAX(0, NORMINV(RAND(), $N$7, $N$8)), $B$7/SQRT($B$9)) -> 22.266312 | G29: =F29-B29 -> 15.167253 | H29: =G29/($B$7*SQRT(2/$B$9)) -> 1.9168566 | I29: =_xlfn.T.DIST.RT(H29, 2*$B$9-2) -> 0.028253108 | J29: =IF(AND(I29<$B$10, G29>=$B$11), 1, 0) -> 0 | K29: {=_xlfn.IFS(G29<$B$11,"Fail",G29<25,"Marginal",G29<35,"Solid",TRUE,"Blowout")} -> Fail | L29: =IF(AND(E29<$B$10,C29>=$B$11),1,0) -> 0 | M29: {=_xlfn.IFS(C29<$B$11,"Fail",C29<25,"Marginal",C29<35,"Solid",TRUE,"Blowout")} -> Fail | P29: Solid | Q29: =COUNTIF(K16:K1005,"Solid")/1000 -> 0.182
A30: =NORMINV(RAND(), MAX(0, NORMINV(RAND(), $B$6, $B$12)), $B$7/SQRT($B$9)) -> 20.93487 | B30: =NORMINV(RAND(), $B$8, $B$7/SQRT($B$9)) -> 14.557187 | C30: =A30-B30 -> 6.3776837 | D30: =C30/($B$7*SQRT(2/$B$9)) -> 0.80601969 | E30: =_xlfn.T.DIST.RT(D30, 2*$B$9-2) -> 0.21053568 | F30: =NORMINV(RAND(), MAX(0, NORMINV(RAND(), $N$7, $N$8)), $B$7/SQRT($B$9)) -> 29.928076 | G30: =F30-B30 -> 15.370889 | H30: =G30/($B$7*SQRT(2/$B$9)) -> 1.9425923 | I30: =_xlfn.T.DIST.RT(H30, 2*$B$9-2) -> 0.026648401 | J30: =IF(AND(I30<$B$10, G30>=$B$11), 1, 0) -> 0 | K30: {=_xlfn.IFS(G30<$B$11,"Fail",G30<25,"Marginal",G30<35,"Solid",TRUE,"Blowout")} -> Fail | L30: =IF(AND(E30<$B$10,C30>=$B$11),1,0) -> 0 | M30: {=_xlfn.IFS(C30<$B$11,"Fail",C30<25,"Marginal",C30<35,"Solid",TRUE,"Blowout")} -> Fail | P30: Blowout | Q30: =COUNTIF(K16:K1005,"Blowout")/1000 -> 0.239
A31: =NORMINV(RAND(), MAX(0, NORMINV(RAND(), $B$6, $B$12)), $B$7/SQRT($B$9)) -> 8.2200464 | B31: =NORMINV(RAND(), $B$8, $B$7/SQRT($B$9)) -> 1.9734183 | C31: =A31-B31 -> 6.246628 | D31: =C31/($B$7*SQRT(2/$B$9)) -> 0.78945671 | E31: =_xlfn.T.DIST.RT(D31, 2*$B$9-2) -> 0.21533267 | F31: =NORMINV(RAND(), MAX(0, NORMINV(RAND(), $N$7, $N$8)), $B$7/SQRT($B$9)) -> 6.4529904 | G31: =F31-B31 -> 4.4795721 | H31: =G31/($B$7*SQRT(2/$B$9)) -> 0.56613396 | I31: =_xlfn.T.DIST.RT(H31, 2*$B$9-2) -> 0.28592976 | J31: =IF(AND(I31<$B$10, G31>=$B$11), 1, 0) -> 0 | K31: {=_xlfn.IFS(G31<$B$11,"Fail",G31<25,"Marginal",G31<35,"Solid",TRUE,"Blowout")} -> Fail | L31: =IF(AND(E31<$B$10,C31>=$B$11),1,0) -> 0 | M31: {=_xlfn.IFS(C31<$B$11,"Fail",C31<25,"Marginal",C31<35,"Solid",TRUE,"Blowout")} -> Fail
A32: =NORMINV(RAND(), MAX(0, NORMINV(RAND(), $B$6, $B$12)), $B$7/SQRT($B$9)) -> 11.747796 | B32: =NORMINV(RAND(), $B$8, $B$7/SQRT($B$9)) -> 1.8675237 | C32: =A32-B32 -> 9.880272 | D32: =C32/($B$7*SQRT(2/$B$9)) -> 1.2486812 | E32: =_xlfn.T.DIST.RT(D32, 2*$B$9-2) -> 0.10653115 | F32: =NORMINV(RAND(), MAX(0, NORMINV(RAND(), $N$7, $N$8)), $B$7/SQRT($B$9)) -> 21.065703 | G32: =F32-B32 -> 19.198179 | H32: =G32/($B$7*SQRT(2/$B$9)) -> 2.42629 | I32: =_xlfn.T.DIST.RT(H32, 2*$B$9-2) -> 0.0080155342 | J32: =IF(AND(I32<$B$10, G32>=$B$11), 1, 0) -> 0 | K32: {=_xlfn.IFS(G32<$B$11,"Fail",G32<25,"Marginal",G32<35,"Solid",TRUE,"Blowout")} -> Fail | L32: =IF(AND(E32<$B$10,C32>=$B$11),1,0) -> 0 | M32: {=_xlfn.IFS(C32<$B$11,"Fail",C32<25,"Marginal",C32<35,"Solid",TRUE,"Blowout")} -> Fail | P32: Avg Posterior Δ
A33: =NORMINV(RAND(), MAX(0, NORMINV(RAND(), $B$6, $B$12)), $B$7/SQRT($B$9)) -> 6.4401077 | B33: =NORMINV(RAND(), $B$8, $B$7/SQRT($B$9)) -> 9.2836347 | C33: =A33-B33 -> -2.843527 | D33: =C33/($B$7*SQRT(2/$B$9)) -> -0.35936852 | E33: =_xlfn.T.DIST.RT(D33, 2*$B$9-2) -> 0.64017399 | F33: =NORMINV(RAND(), MAX(0, NORMINV(RAND(), $N$7, $N$8)), $B$7/SQRT($B$9)) -> 43.741953 | G33: =F33-B33 -> 34.458318 | H33: =G33/($B$7*SQRT(2/$B$9)) -> 4.3548855 | I33: =_xlfn.T.DIST.RT(H33, 2*$B$9-2) -> 1.0060465e-05 | J33: =IF(AND(I33<$B$10, G33>=$B$11), 1, 0) -> 1 | K33: {=_xlfn.IFS(G33<$B$11,"Fail",G33<25,"Marginal",G33<35,"Solid",TRUE,"Blowout")} -> Solid | L33: =IF(AND(E33<$B$10,C33>=$B$11),1,0) -> 0 | M33: {=_xlfn.IFS(C33<$B$11,"Fail",C33<25,"Marginal",C33<35,"Solid",TRUE,"Blowout")} -> Fail | P33: Mean Post. Delta (m) | Q33: =AVERAGE(G16:G1005) -> 21.322449
A34: =NORMINV(RAND(), MAX(0, NORMINV(RAND(), $B$6, $B$12)), $B$7/SQRT($B$9)) -> 26.865209 | B34: =NORMINV(RAND(), $B$8, $B$7/SQRT($B$9)) -> 0.28807676 | C34: =A34-B34 -> 26.577133 | D34: =C34/($B$7*SQRT(2/$B$9)) -> 3.3588515 | E34: =_xlfn.T.DIST.RT(D34, 2*$B$9-2) -> 0.00045861441 | F34: =NORMINV(RAND(), MAX(0, NORMINV(RAND(), $N$7, $N$8)), $B$7/SQRT($B$9)) -> 19.428343 | G34: =F34-B34 -> 19.140266 | H34: =G34/($B$7*SQRT(2/$B$9)) -> 2.4189709 | I34: =_xlfn.T.DIST.RT(H34, 2*$B$9-2) -> 0.0081744036 | J34: =IF(AND(I34<$B$10, G34>=$B$11), 1, 0) -> 0 | K34: {=_xlfn.IFS(G34<$B$11,"Fail",G34<25,"Marginal",G34<35,"Solid",TRUE,"Blowout")} -> Fail | L34: =IF(AND(E34<$B$10,C34>=$B$11),1,0) -> 1 | M34: {=_xlfn.IFS(C34<$B$11,"Fail",C34<25,"Marginal",C34<35,"Solid",TRUE,"Blowout")} -> Solid
A35: =NORMINV(RAND(), MAX(0, NORMINV(RAND(), $B$6, $B$12)), $B$7/SQRT($B$9)) -> 29.304401 | B35: =NORMINV(RAND(), $B$8, $B$7/SQRT($B$9)) -> 1.8905319 | C35: =A35-B35 -> 27.413869 | D35: =C35/($B$7*SQRT(2/$B$9)) -> 3.4645992 | E35: =_xlfn.T.DIST.RT(D35, 2*$B$9-2) -> 0.00031713136 | F35: =NORMINV(RAND(), MAX(0, NORMINV(RAND(), $N$7, $N$8)), $B$7/SQRT($B$9)) -> 23.322148 | G35: =F35-B35 -> 21.431616 | H35: =G35/($B$7*SQRT(2/$B$9)) -> 2.7085545 | I35: =_xlfn.T.DIST.RT(H35, 2*$B$9-2) -> 0.0036351669 | J35: =IF(AND(I35<$B$10, G35>=$B$11), 1, 0) -> 1 | K35: {=_xlfn.IFS(G35<$B$11,"Fail",G35<25,"Marginal",G35<35,"Solid",TRUE,"Blowout")} -> Marginal | L35: =IF(AND(E35<$B$10,C35>=$B$11),1,0) -> 1 | M35: {=_xlfn.IFS(C35<$B$11,"Fail",C35<25,"Marginal",C35<35,"Solid",TRUE,"Blowout")} -> Solid
A36: =NORMINV(RAND(), MAX(0, NORMINV(RAND(), $B$6, $B$12)), $B$7/SQRT($B$9)) -> 45.660709 | B36: =NORMINV(RAND(), $B$8, $B$7/SQRT($B$9)) -> 1.0583735 | C36: =A36-B36 -> 44.602335 | D36: =C36/($B$7*SQRT(2/$B$9)) -> 5.6368992 | E36: =_xlfn.T.DIST.RT(D36, 2*$B$9-2) -> 2.5446888e-08 | F36: =NORMINV(RAND(), MAX(0, NORMINV(RAND(), $N$7, $N$8)), $B$7/SQRT($B$9)) -> -2.0437203 | G36: =F36-B36 -> -3.1020939 | H36: =G36/($B$7*SQRT(2/$B$9)) -> -0.39204652 | I36: =_xlfn.T.DIST.RT(H36, 2*$B$9-2) -> 0.65230498 | J36: =IF(AND(I36<$B$10, G36>=$B$11), 1, 0) -> 0 | K36: {=_xlfn.IFS(G36<$B$11,"Fail",G36<25,"Marginal",G36<35,"Solid",TRUE,"Blowout")} -> Fail | L36: =IF(AND(E36<$B$10,C36>=$B$11),1,0) -> 1 | M36: {=_xlfn.IFS(C36<$B$11,"Fail",C36<25,"Marginal",C36<35,"Solid",TRUE,"Blowout")} -> Blowout
A37: =NORMINV(RAND(), MAX(0, NORMINV(RAND(), $B$6, $B$12)), $B$7/SQRT($B$9)) -> 11.121441 | B37: =NORMINV(RAND(), $B$8, $B$7/SQRT($B$9)) -> 3.6847718 | C37: =A37-B37 -> 7.4366689 | D37: =C37/($B$7*SQRT(2/$B$9)) -> 0.93985556 | E37: =_xlfn.T.DIST.RT(D37, 2*$B$9-2) -> 0.17414315 | F37: =NORMINV(RAND(), MAX(0, NORMINV(RAND(), $N$7, $N$8)), $B$7/SQRT($B$9)) -> 30.88521 | G37: =F37-B37 -> 27.200439 | H37: =G37/($B$7*SQRT(2/$B$9)) -> 3.4376256 | I37: =_xlfn.T.DIST.RT(H37, 2*$B$9-2) -> 0.00034871563 | J37: =IF(AND(I37<$B$10, G37>=$B$11), 1, 0) -> 1 | K37: {=_xlfn.IFS(G37<$B$11,"Fail",G37<25,"Marginal",G37<35,"Solid",TRUE,"Blowout")} -> Solid | L37: =IF(AND(E37<$B$10,C37>=$B$11),1,0) -> 0 | M37: {=_xlfn.IFS(C37<$B$11,"Fail",C37<25,"Marginal",C37<35,"Solid",TRUE,"Blowout")} -> Fail
A38: =NORMINV(RAND(), MAX(0, NORMINV(RAND(), $B$6, $B$12)), $B$7/SQRT($B$9)) -> 21.237417 | B38: =NORMINV(RAND(), $B$8, $B$7/SQRT($B$9)) -> 3.9335048 | C38: =A38-B38 -> 17.303912 | D38: =C38/($B$7*SQRT(2/$B$9)) -> 2.1868901 | E38: =_xlfn.T.DIST.RT(D38, 2*$B$9-2) -> 0.014883739 | F38: =NORMINV(RAND(), MAX(0, NORMINV(RAND(), $N$7, $N$8)), $B$7/SQRT($B$9)) -> 39.105521 | G38: =F38-B38 -> 35.172017 | H38: =G38/($B$7*SQRT(2/$B$9)) -> 4.4450837 | I38: =_xlfn.T.DIST.RT(H38, 2*$B$9-2) -> 6.8593702e-06 | J38: =IF(AND(I38<$B$10, G38>=$B$11), 1, 0) -> 1 | K38: {=_xlfn.IFS(G38<$B$11,"Fail",G38<25,"Marginal",G38<35,"Solid",TRUE,"Blowout")} -> Blowout | L38: =IF(AND(E38<$B$10,C38>=$B$11),1,0) -> 0 | M38: {=_xlfn.IFS(C38<$B$11,"Fail",C38<25,"Marginal",C38<35,"Solid",TRUE,"Blowout")} -> Fail
A39: =NORMINV(RAND(), MAX(0, NORMINV(RAND(), $B$6, $B$12)), $B$7/SQRT($B$9)) -> 15.635192 | B39: =NORMINV(RAND(), $B$8, $B$7/SQRT($B$9)) -> 15.086976 | C39: =A39-B39 -> 0.54821675 | D39: =C39/($B$7*SQRT(2/$B$9)) -> 0.069284323 | E39: =_xlfn.T.DIST.RT(D39, 2*$B$9-2) -> 0.47241202 | F39: =NORMINV(RAND(), MAX(0, NORMINV(RAND(), $N$7, $N$8)), $B$7/SQRT($B$9)) -> -2.4848425 | G39: =F39-B39 -> -17.571818 | H39: =G39/($B$7*SQRT(2/$B$9)) -> -2.2207485 | I39: =_xlfn.T.DIST.RT(H39, 2*$B$9-2) -> 0.98632416 | J39: =IF(AND(I39<$B$10, G39>=$B$11), 1, 0) -> 0 | K39: {=_xlfn.IFS(G39<$B$11,"Fail",G39<25,"Marginal",G39<35,"Solid",TRUE,"Blowout")} -> Fail | L39: =IF(AND(E39<$B$10,C39>=$B$11),1,0) -> 0 | M39: {=_xlfn.IFS(C39<$B$11,"Fail",C39<25,"Marginal",C39<35,"Solid",TRUE,"Blowout")} -> Fail
A40: =NORMINV(RAND(), MAX(0, NORMINV(RAND(), $B$6, $B$12)), $B$7/SQRT($B$9)) -> 12.643878 | B40: =NORMINV(RAND(), $B$8, $B$7/SQRT($B$9)) -> 2.5530195 | C40: =A40-B40 -> 10.090859 | D40: =C40/($B$7*SQRT(2/$B$9)) -> 1.2752954 | E40: =_xlfn.T.DIST.RT(D40, 2*$B$9-2) -> 0.1017513 | F40: =NORMINV(RAND(), MAX(0, NORMINV(RAND(), $N$7, $N$8)), $B$7/SQRT($B$9)) -> 31.154854 | G40: =F40-B40 -> 28.601835 | H40: =G40/($B$7*SQRT(2/$B$9)) -> 3.6147358 | I40: =_xlfn.T.DIST.RT(H40, 2*$B$9-2) -> 0.00018499911 | J40: =IF(AND(I40<$B$10, G40>=$B$11), 1, 0) -> 1 | K40: {=_xlfn.IFS(G40<$B$11,"Fail",G40<25,"Marginal",G40<35,"Solid",TRUE,"Blowout")} -> Solid | L40: =IF(AND(E40<$B$10,C40>=$B$11),1,0) -> 0 | M40: {=_xlfn.IFS(C40<$B$11,"Fail",C40<25,"Marginal",C40<35,"Solid",TRUE,"Blowout")} -> Fail
A41: =NORMINV(RAND(), MAX(0, NORMINV(RAND(), $B$6, $B$12)), $B$7/SQRT($B$9)) -> 18.45245 | B41: =NORMINV(RAND(), $B$8, $B$7/SQRT($B$9)) -> 0.78247823 | C41: =A41-B41 -> 17.669972 | D41: =C41/($B$7*SQRT(2/$B$9)) -> 2.2331533 | E41: =_xlfn.T.DIST.RT(D41, 2*$B$9-2) -> 0.013255104 | F41: =NORMINV(RAND(), MAX(0, NORMINV(RAND(), $N$7, $N$8)), $B$7/SQRT($B$9)) -> 37.945571 | G41: =F41-B41 -> 37.163093 | H41: =G41/($B$7*SQRT(2/$B$9)) -> 4.6967184 | I41: =_xlfn.T.DIST.RT(H41, 2*$B$9-2) -> 2.2839057e-06 | J41: =IF(AND(I41<$B$10, G41>=$B$11), 1, 0) -> 1 | K41: {=_xlfn.IFS(G41<$B$11,"Fail",G41<25,"Marginal",G41<35,"Solid",TRUE,"Blowout")} -> Blowout | L41: =IF(AND(E41<$B$10,C41>=$B$11),1,0) -> 0 | M41: {=_xlfn.IFS(C41<$B$11,"Fail",C41<25,"Marginal",C41<35,"Solid",TRUE,"Blowout")} -> Fail
A42: =NORMINV(RAND(), MAX(0, NORMINV(RAND(), $B$6, $B$12)), $B$7/SQRT($B$9)) -> 47.442739 | B42: =NORMINV(RAND(), $B$8, $B$7/SQRT($B$9)) -> 5.4206547 | C42: =A42-B42 -> 42.022084 | D42: =C42/($B$7*SQRT(2/$B$9)) -> 5.3108038 | E42: =_xlfn.T.DIST.RT(D42, 2*$B$9-2) -> 1.2946007e-07 | F42: =NORMINV(RAND(), MAX(0, NORMINV(RAND(), $N$7, $N$8)), $B$7/SQRT($B$9)) -> 26.945017 | G42: =F42-B42 -> 21.524363 | H42: =G42/($B$7*SQRT(2/$B$9)) -> 2.720276 | I42: =_xlfn.T.DIST.RT(H42, 2*$B$9-2) -> 0.0035127386 | J42: =IF(AND(I42<$B$10, G42>=$B$11), 1, 0) -> 1 | K42: {=_xlfn.IFS(G42<$B$11,"Fail",G42<25,"Marginal",G42<35,"Solid",TRUE,"Blowout")} -> Marginal | L42: =IF(AND(E42<$B$10,C42>=$B$11),1,0) -> 1 | M42: {=_xlfn.IFS(C42<$B$11,"Fail",C42<25,"Marginal",C42<35,"Solid",TRUE,"Blowout")} -> Blowout
A43: =NORMINV(RAND(), MAX(0, NORMINV(RAND(), $B$6, $B$12)), $B$7/SQRT($B$9)) -> 38.505162 | B43: =NORMINV(RAND(), $B$8, $B$7/SQRT($B$9)) -> -3.7093177 | C43: =A43-B43 -> 42.21448 | D43: =C43/($B$7*SQRT(2/$B$9)) -> 5.335119 | E43: =_xlfn.T.DIST.RT(D43, 2*$B$9-2) -> 1.1494594e-07 | F43: =NORMINV(RAND(), MAX(0, NORMINV(RAND(), $N$7, $N$8)), $B$7/SQRT($B$9)) -> 38.286482 | G43: =F43-B43 -> 41.9958 | H43: =G43/($B$7*SQRT(2/$B$9)) -> 5.307482 | I43: =_xlfn.T.DIST.RT(H43, 2*$B$9-2) -> 1.3157632e-07 | J43: =IF(AND(I43<$B$10, G43>=$B$11), 1, 0) -> 1 | K43: {=_xlfn.IFS(G43<$B$11,"Fail",G43<25,"Marginal",G43<35,"Solid",TRUE,"Blowout")} -> Blowout | L43: =IF(AND(E43<$B$10,C43>=$B$11),1,0) -> 1 | M43: {=_xlfn.IFS(C43<$B$11,"Fail",C43<25,"Marginal",C43<35,"Solid",TRUE,"Blowout")} -> Blowout
A44: =NORMINV(RAND(), MAX(0, NORMINV(RAND(), $B$6, $B$12)), $B$7/SQRT($B$9)) -> 27.041055 | B44: =NORMINV(RAND(), $B$8, $B$7/SQRT($B$9)) -> 0.92874897 | C44: =A44-B44 -> 26.112306 | D44: =C44/($B$7*SQRT(2/$B$9)) -> 3.300106 | E44: =_xlfn.T.DIST.RT(D44, 2*$B$9-2) -> 0.0005607548 | F44: =NORMINV(RAND(), MAX(0, NORMINV(RAND(), $N$7, $N$8)), $B$7/SQRT($B$9)) -> 21.807598 | G44: =F44-B44 -> 20.878849 | H44: =G44/($B$7*SQRT(2/$B$9)) -> 2.6386952 | I44: =_xlfn.T.DIST.RT(H44, 2*$B$9-2) -> 0.00444815 | J44: =IF(AND(I44<$B$10, G44>=$B$11), 1, 0) -> 1 | K44: {=_xlfn.IFS(G44<$B$11,"Fail",G44<25,"Marginal",G44<35,"Solid",TRUE,"Blowout")} -> Marginal | L44: =IF(AND(E44<$B$10,C44>=$B$11),1,0) -> 1 | M44: {=_xlfn.IFS(C44<$B$11,"Fail",C44<25,"Marginal",C44<35,"Solid",TRUE,"Blowout")} -> Solid
...

Sheet Base Case (Normal)
A1: TENX — Monte Carlo Simulation
A2: Base Case | σ=50m, Mean=35m, n=115 | PoS ~56%
A6: SIMULATION PARAMETERS | F6: SIMULATION RESULTS
A7: Simulations (n) | B7: 1000 | F7: Avg Mean Δ6MWD (m) | G7: =AVERAGE(B16:B1015) -> 39.097525
A8: Patients (Treatment Arm) | B8: 115 | F8: 95% CI Low (2.5th pct) | G8: =PERCENTILE(B16:B1015, 0.025) -> -59.440546
A9: Expected Mean Δ6MWD (m) | B9: 35 | F9: 95% CI High (97.5th pct) | G9: =PERCENTILE(B16:B1015, 0.975) -> 132.02071
A10: Std Dev (m) | B10: 50 | F10: Probability of Success | G10: =AVERAGE(C16:C1015) -> 0.621
A11: Success Threshold (m) | B11: 25 | F11: Success Threshold | G11: 25
F12: Simulations Run | G12: 1000
A15: Sim # | B15: Mean Δ6MWD (m) | C15: Success (≥25m) | D15: Δ6MWD Range (m) | E15: Frequency
A16: 1 | B16: =_xlfn.NORM.INV(RAND(), $B$9, $B$10) -> 48.192101 | C16: =IF(B16 >= $B$11, 1, 0) -> 1 | D16: -100 to -75 | E16: =COUNTIFS(B16:B1015,">=-100",B16:B1015,"<-75") -> 9
A17: =+A16+1 -> 2 | B17: =_xlfn.NORM.INV(RAND(), $B$9, $B$10) -> 139.66811 | C17: =IF(B17 >= $B$11, 1, 0) -> 1 | D17: -75 to -25 | E17: =COUNTIFS(B16:B1015,">=-75",B16:B1015,"<-25") -> 97
A18: =+A17+1 -> 3 | B18: =_xlfn.NORM.INV(RAND(), $B$9, $B$10) -> 87.683075 | C18: =IF(B18 >= $B$11, 1, 0) -> 1 | D18: -25 to 25 | E18: =COUNTIFS(B16:B1015,">=-25",B16:B1015,"<25") -> 273
A19: =+A18+1 -> 4 | B19: =_xlfn.NORM.INV(RAND(), $B$9, $B$10) -> 80.437341 | C19: =IF(B19 >= $B$11, 1, 0) -> 1 | D19: 25 to 75 | E19: =COUNTIFS(B16:B1015,">=25",B16:B1015,"<75") -> 380
A20: =+A19+1 -> 5 | B20: =_xlfn.NORM.INV(RAND(), $B$9, $B$10) -> 59.835499 | C20: =IF(B20 >= $B$11, 1, 0) -> 1 | D20: 75 to 125 | E20: =COUNTIFS(B16:B1015,">=75",B16:B1015,"<125") -> 205
A21: =+A20+1 -> 6 | B21: =_xlfn.NORM.INV(RAND(), $B$9, $B$10) -> -5.0244928 | C21: =IF(B21 >= $B$11, 1, 0) -> 0 | D21: 125 to 175 | E21: =COUNTIFS(B16:B1015,">=125",B16:B1015,"<175") -> 36
A22: =+A21+1 -> 7 | B22: =_xlfn.NORM.INV(RAND(), $B$9, $B$10) -> 74.241902 | C22: =IF(B22 >= $B$11, 1, 0) -> 1
A23: =+A22+1 -> 8 | B23: =_xlfn.NORM.INV(RAND(), $B$9, $B$10) -> -82.109899 | C23: =IF(B23 >= $B$11, 1, 0) -> 0
A24: =+A23+1 -> 9 | B24: =_xlfn.NORM.INV(RAND(), $B$9, $B$10) -> 67.18341 | C24: =IF(B24 >= $B$11, 1, 0) -> 1
A25: =+A24+1 -> 10 | B25: =_xlfn.NORM.INV(RAND(), $B$9, $B$10) -> -29.757327 | C25: =IF(B25 >= $B$11, 1, 0) -> 0
A26: =+A25+1 -> 11 | B26: =_xlfn.NORM.INV(RAND(), $B$9, $B$10) -> 66.113781 | C26: =IF(B26 >= $B$11, 1, 0) -> 1
A27: =+A26+1 -> 12 | B27: =_xlfn.NORM.INV(RAND(), $B$9, $B$10) -> 37.910231 | C27: =IF(B27 >= $B$11, 1, 0) -> 1
A28: =+A27+1 -> 13 | B28: =_xlfn.NORM.INV(RAND(), $B$9, $B$10) -> 67.390326 | C28: =IF(B28 >= $B$11, 1, 0) -> 1
A29: =+A28+1 -> 14 | B29: =_xlfn.NORM.INV(RAND(), $B$9, $B$10) -> -0.13094487 | C29: =IF(B29 >= $B$11, 1, 0) -> 0
A30: =+A29+1 -> 15 | B30: =_xlfn.NORM.INV(RAND(), $B$9, $B$10) -> 62.178446 | C30: =IF(B30 >= $B$11, 1, 0) -> 1
A31: =+A30+1 -> 16 | B31: =_xlfn.NORM.INV(RAND(), $B$9, $B$10) -> 97.239531 | C31: =IF(B31 >= $B$11, 1, 0) -> 1
A32: =+A31+1 -> 17 | B32: =_xlfn.NORM.INV(RAND(), $B$9, $B$10) -> -24.931025 | C32: =IF(B32 >= $B$11, 1, 0) -> 0
A33: =+A32+1 -> 18 | B33: =_xlfn.NORM.INV(RAND(), $B$9, $B$10) -> 38.3728 | C33: =IF(B33 >= $B$11, 1, 0) -> 1
... A1015: =+A1014+1 -> 1000 | B1015: =_xlfn.NORM.INV(RAND(), $B$9, $B$10) -> 39.946468 | C1015: =IF(B1015 >= $B$11, 1, 0) -> 1

Sheet Bull Case (Phase 2 Prior)
A1: TENX — Monte Carlo Simulation
A2: Bull Case | σ=25m (Phase 2 tightened), Mean=35m, n=115 | PoS ~63%
A6: SIMULATION PARAMETERS | F6: SIMULATION RESULTS
A7: Simulations (n) | B7: 1000 | F7: Avg Mean Δ6MWD (m) | G7: =AVERAGE(B16:B1015) -> 35.58139
A8: Patients (Treatment Arm) | B8: 115 | F8: 95% CI Low (2.5th pct) | G8: =PERCENTILE(B16:B1015, 0.025) -> -14.620282
A9: Expected Mean Δ6MWD (m) | B9: 35 | F9: 95% CI High (97.5th pct) | G9: =PERCENTILE(B16:B1015, 0.975) -> 84.226612
A10: Std Dev (m) | B10: 25 | F10: Probability of Success | G10: =AVERAGE(C16:C1015) -> 0.666
A11: Success Threshold (m) | B11: 25 | F11: Success Threshold | G11: 25
F12: Simulations Run | G12: 1000
A15: Sim # | B15: Mean Δ6MWD (m) | C15: Success (≥25m) | D15: Δ6MWD Range (m) | E15: Frequency
A16: 1 | B16: =_xlfn.NORM.INV(RAND(), $B$9, $B$10) -> 30.304496 | C16: =IF(B16 >= $B$11, 1, 0) -> 1 | D16: -75 to -50 | E16: =COUNTIFS(B16:B1015,">=-75",B16:B1015,"<-50") -> 0
A17: =+A16+1 -> 2 | B17: =_xlfn.NORM.INV(RAND(), $B$9, $B$10) -> 52.981337 | C17: =IF(B17 >= $B$11, 1, 0) -> 1 | D17: -50 to -25 | E17: =COUNTIFS(B16:B1015,">=-50",B16:B1015,"<-25") -> 10
A18: =+A17+1 -> 3 | B18: =_xlfn.NORM.INV(RAND(), $B$9, $B$10) -> 41.250978 | C18: =IF(B18 >= $B$11, 1, 0) -> 1 | D18: -25 to 0 | E18: =COUNTIFS(B16:B1015,">=-25",B16:B1015,"<0") -> 64
A19: =+A18+1 -> 4 | B19: =_xlfn.NORM.INV(RAND(), $B$9, $B$10) -> 48.080155 | C19: =IF(B19 >= $B$11, 1, 0) -> 1 | D19: 0 to 25 | E19: =COUNTIFS(B16:B1015,">=0",B16:B1015,"<25") -> 260
A20: =+A19+1 -> 5 | B20: =_xlfn.NORM.INV(RAND(), $B$9, $B$10) -> 39.46214 | C20: =IF(B20 >= $B$11, 1, 0) -> 1 | D20: 25 to 50 | E20: =COUNTIFS(B16:B1015,">=25",B16:B1015,"<50") -> 381
A21: =+A20+1 -> 6 | B21: =_xlfn.NORM.INV(RAND(), $B$9, $B$10) -> 38.074434 | C21: =IF(B21 >= $B$11, 1, 0) -> 1 | D21: 50 to 75 | E21: =COUNTIFS(B16:B1015,">=50",B16:B1015,"<75") -> 232
A22: =+A21+1 -> 7 | B22: =_xlfn.NORM.INV(RAND(), $B$9, $B$10) -> 29.160018 | C22: =IF(B22 >= $B$11, 1, 0) -> 1 | D22: 75 to 100 | E22: =COUNTIFS(B16:B1015,">=75",B16:B1015,"<100") -> 50
A23: =+A22+1 -> 8 | B23: =_xlfn.NORM.INV(RAND(), $B$9, $B$10) -> 84.816807 | C23: =IF(B23 >= $B$11, 1, 0) -> 1 | D23: 100 to 125 | E23: =COUNTIFS(B16:B1015,">=100",B16:B1015,"<125") -> 3
A24: =+A23+1 -> 9 | B24: =_xlfn.NORM.INV(RAND(), $B$9, $B$10) -> 44.396315 | C24: =IF(B24 >= $B$11, 1, 0) -> 1
A25: =+A24+1 -> 10 | B25: =_xlfn.NORM.INV(RAND(), $B$9, $B$10) -> 50.595826 | C25: =IF(B25 >= $B$11, 1, 0) -> 1
A26: =+A25+1 -> 11 | B26: =_xlfn.NORM.INV(RAND(), $B$9, $B$10) -> 52.29508 | C26: =IF(B26 >= $B$11, 1, 0) -> 1
A27: =+A26+1 -> 12 | B27: =_xlfn.NORM.INV(RAND(), $B$9, $B$10) -> 38.604418 | C27: =IF(B27 >= $B$11, 1, 0) -> 1
A28: =+A27+1 -> 13 | B28: =_xlfn.NORM.INV(RAND(), $B$9, $B$10) -> 8.409497 | C28: =IF(B28 >= $B$11, 1, 0) -> 0
A29: =+A28+1 -> 14 | B29: =_xlfn.NORM.INV(RAND(), $B$9, $B$10) -> 10.053398 | C29: =IF(B29 >= $B$11, 1, 0) -> 0
A30: =+A29+1 -> 15 | B30: =_xlfn.NORM.INV(RAND(), $B$9, $B$10) -> 41.68322 | C30: =IF(B30 >= $B$11, 1, 0) -> 1
A31: =+A30+1 -> 16 | B31: =_xlfn.NORM.INV(RAND(), $B$9, $B$10) -> 29.903247 | C31: =IF(B31 >= $B$11, 1, 0) -> 1
A32: =+A31+1 -> 17 | B32: =_xlfn.NORM.INV(RAND(), $B$9, $B$10) -> 18.820184 | C32: =IF(B32 >= $B$11, 1, 0) -> 0
A33: =+A32+1 -> 18 | B33: =_xlfn.NORM.INV(RAND(), $B$9, $B$10) -> 11.180395 | C33: =IF(B33 >= $B$11, 1, 0) -> 0
A34: =+A33+1 -> 19 | B34: =_xlfn.NORM.INV(RAND(), $B$9, $B$10) -> 58.271774 | C34: =IF(B34 >= $B$11, 1, 0) -> 1
A35: =+A34+1 -> 20 | B35: =_xlfn.NORM.INV(RAND(), $B$9, $B$10) -> 41.499374 | C35: =IF(B35 >= $B$11, 1, 0) -> 1
... A1015: =+A1014+1 -> 1000 | B1015: =_xlfn.NORM.INV(RAND(), $B$9, $B$10) -> 18.378685 | C1015: =IF(B1015 >= $B$11, 1, 0) -> 0

Sheet DCF
A1: TENX | C1: TENX — DCF Valuation Model
A2: DCF | C2: Risk-Adjusted NPV Analysis
A4: SUMMARY | C4: KEY ASSUMPTIONS
D5: Discount Rate (WACC) | E5: 0.12 | F5: Probability of Success | G5: 0.5 | H5: Market Size ($M) | I5: 6740 | J5: Tax Rate | K5: 0.21 | L5: Launch Year | M5: 2029 | N5: Patent Expiry | O5: 2040
A7: RNPV | C7: Year | D7: Phase | E7: Share % | F7: Revenue ($M) | G7: COGS ($M) | H7: R&D ($M) | I7: OPEX ($M) | J7: EBIT ($M) | K7: BEG. NOL ($M) | L7: TAX ($M) | M7: UNADJ. FCF ($M) | N7: POS % | O7: RISK-ADJ FCF | P7: RNPV (CUM) | R7: Year | S7: Phase | T7: Risk-Adj FCF ($M) | U7: Cumulative RNPV ($M)
A8: $320M | C8: 2026 | D8: DEV | E8: 0 | F8: 0 | G8: 0 | H8: -40 | I8: 0 | J8: =+F8+SUM(G8:I8) -> -40 | K8: 56.4 | L8: 0 | M8: =+J8 -> -40 | N8: NA | O8: =+M8 -> -40 | P8: -35.4 | R8: 2026 | S8: DEV | T8: -40 | U8: -35.4
A9: Risk-Adj. Net Present Value | C9: =+C8+1 -> 2027 | D9: DEV | E9: 0 | F9: 0 | G9: 0 | H9: -40 | I9: 0 | J9: =+F9+SUM(G9:I9) -> -40 | K9: 96.4 | L9: 0 | M9: =+J9 -> -40 | N9: NA | O9: =+M9 -> -40 | P9: -66.7 | R9: 2027 | S9: DEV | T9: -40 | U9: -66.7
C10: =+C9+1 -> 2028 | D10: DEV | E10: 0 | F10: 0 | G10: 0 | H10: -40 | I10: 0 | J10: =+F10+SUM(G10:I10) -> -40 | K10: 136.4 | L10: 0 | M10: =+J10 -> -40 | N10: NA | O10: =+M10 -> -40 | P10: -94.4 | R10: 2028 | S10: DEV | T10: -40 | U10: -94.4
A11: Peak Revenue | C11: =+C10+1 -> 2029 | D11: BRAND | E11: 0.015 | F11: 56.5 | G11: -4.5 | H11: 0 | I11: -31.1 | J11: =+F11+SUM(G11:I11) -> 20.9 | K11: 176.4 | L11: =-J11*0.045 -> -0.9405 | M11: =+J11+L11 -> 19.9595 | N11: 0.5 | O11: =+M11*N11 -> 9.97975 | P11: -88.3 | R11: 2029 | S11: BRAND | T11: 9.98 | U11: -88.3
A12: $742M | C12: =+C11+1 -> 2030 | D12: BRAND | E12: 0.038 | F12: 144.9 | G12: -11.6 | H12: 0 | I12: -79.9 | J12: =+F12+SUM(G12:I12) -> 53.4 | K12: 159.7 | L12: =-J12*0.045 -> -2.403 | M12: =+J12+L12 -> 50.997 | N12: 0.5 | O12: =+M12*N12 -> 25.4985 | P12: -74.4 | R12: 2030 | S12: BRAND | T12: 25.5 | U12: -74.4
A13: (2040, BRAND phase) | C13: =+C12+1 -> 2031 | D13: BRAND | E13: 0.06 | F13: 237.6 | G13: -19 | H13: 0 | I13: -130.7 | J13: =+F13+SUM(G13:I13) -> 87.9 | K13: 116.8 | L13: =-J13*0.045 -> -3.9555 | M13: =+J13+L13 -> 83.9445 | N13: 0.5 | O13: =+M13*N13 -> 41.97225 | P13: -54.1 | R13: 2031 | S13: BRAND | T13: 41.97 | U13: -54.1
C14: =+C13+1 -> 2032 | D14: BRAND | E14: 0.083 | F14: 334.9 | G14: -26.8 | H14: 0 | I14: -184.2 | J14: =+F14+SUM(G14:I14) -> 123.9 | K14: 46.5 | L14: =-J14*0.13 -> -16.107 | M14: =+J14+L14 -> 107.793 | N14: 0.5 | O14: =+M14*N14 -> 53.8965 | P14: -31.3 | R14: 2032 | S14: BRAND | T14: 53.9 | U14: -31.3
A15: Peak Risk-Adj FCF | C15: =+C14+1 -> 2033 | D15: BRAND | E15: 0.105 | F15: 436.8 | G15: -34.9 | H15: 0 | I15: -131.1 | J15: =+F15+SUM(G15:I15) -> 270.8 | K15: 0 | L15: =-J15*0.21 -> -56.868 | M15: =+J15+L15 -> 213.932 | N15: 0.5 | O15: =+M15*N15 -> 106.966 | P15: 9 | R15: 2033 | S15: BRAND | T15: 106.97 | U15: 9
A16: $182M | C16: =+C15+1 -> 2034 | D16: BRAND | E16: 0.128 | F16: 543.7 | G16: -43.5 | H16: 0 | I16: -163.1 | J16: =+F16+SUM(G16:I16) -> 337.1 | K16: 0 | L16: =-J16*0.21 -> -70.791 | M16: =+J16+L16 -> 266.309 | N16: 0.5 | O16: =+M16*N16 -> 133.1545 | P16: 53.3 | R16: 2034 | S16: BRAND | T16: 133.15 | U16: 53.3
A17: (2040, post-PoS adj.) | C17: =+C16+1 -> 2035 | D17: BRAND | E17: 0.15 | F17: 655.7 | G17: -52.5 | H17: 0 | I17: -196.7 | J17: =+F17+SUM(G17:I17) -> 406.5 | K17: 0 | L17: =-J17*0.21 -> -85.365 | M17: =+J17+L17 -> 321.135 | N17: 0.5 | O17: =+M17*N17 -> 160.5675 | P17: 100.6 | R17: 2035 | S17: BRAND | T17: 160.57 | U17: 100.6
C18: =+C17+1 -> 2036 | D18: BRAND | E18: 0.15 | F18: 672 | G18: -53.8 | H18: 0 | I18: -201.6 | J18: =+F18+SUM(G18:I18) -> 416.6 | K18: 0 | L18: =-J18*0.21 -> -87.486 | M18: =+J18+L18 -> 329.114 | N18: 0.5 | O18: =+M18*N18 -> 164.557 | P18: 143.5 | R18: 2036 | S18: BRAND | T18: 164.56 | U18: 143.5
A19: Breakeven | C19: =+C18+1 -> 2037 | D19: BRAND | E19: 0.15 | F19: 688.8 | G19: -55.1 | H19: 0 | I19: -206.7 | J19: =+F19+SUM(G19:I19) -> 427 | K19: 0 | L19: =-J19*0.21 -> -89.67 | M19: =+J19+L19 -> 337.33 | N19: 0.5 | O19: =+M19*N19 -> 168.665 | P19: 182.4 | R19: 2037 | S19: BRAND | T19: 168.67 | U19: 182.4
A20: 2033 | C20: =+C19+1 -> 2038 | D20: BRAND | E20: 0.15 | F20: 706.1 | G20: -56.5 | H20: 0 | I20: -211.8 | J20: =+F20+SUM(G20:I20) -> 437.8 | K20: 0 | L20: =-J20*0.21 -> -91.938 | M20: =+J20+L20 -> 345.862 | N20: 0.5 | O20: =+M20*N20 -> 172.931 | P20: 217.7 | R20: 2038 | S20: BRAND | T20: 172.93 | U20: 217.7
A21: (RNPV turns positive) | C21: =+C20+1 -> 2039 | D21: BRAND | E21: 0.15 | F21: 723.7 | G21: -57.9 | H21: 0 | I21: -217.1 | J21: =+F21+SUM(G21:I21) -> 448.7 | K21: 0 | L21: =-J21*0.21 -> -94.227 | M21: =+J21+L21 -> 354.473 | N21: 0.5 | O21: =+M21*N21 -> 177.2365 | P21: 249.8 | R21: 2039 | S21: BRAND | T21: 177.24 | U21: 249.8
C22: =+C21+1 -> 2040 | D22: BRAND | E22: 0.15 | F22: 741.8 | G22: -59.3 | H22: 0 | I22: -222.5 | J22: =+F22+SUM(G22:I22) -> 460 | K22: 0 | L22: =-J22*0.21 -> -96.6 | M22: =+J22+L22 -> 363.4 | N22: 0.5 | O22: =+M22*N22 -> 181.7 | P22: 278.8 | R22: 2040 | S22: BRAND | T22: 181.7 | U22: 278.8
A23: PHASES | C23: =+C22+1 -> 2041 | D23: GENERIC | E23: 0.128 | F23: 549.4 | G23: -43.9 | H23: 0 | I23: -164.6 | J23: =+F23+SUM(G23:I23) -> 340.9 | K23: 0 | L23: =-J23*0.21 -> -71.589 | M23: =+J23+L23 -> 269.311 | N23: 0.5 | O23: =+M23*N23 -> 134.6555 | P23: 297.8 | R23: 2041 | S23: GENERIC | T23: 134.66 | U23: 297.8
A24: ■ DEV | B24: 2026–2028 | C24: =+C23+1 -> 2042 | D24: GENERIC | E24: 0.105 | F24: 381.9 | G24: -30.6 | H24: 0 | I24: -114.6 | J24: =+F24+SUM(G24:I24) -> 236.7 | K24: 0 | L24: =-J24*0.21 -> -49.707 | M24: =+J24+L24 -> 186.993 | N24: 0.5 | O24: =+M24*N24 -> 93.4965 | P24: 309.6 | R24: 2042 | S24: GENERIC | T24: 93.5 | U24: 309.6
A25: ■ BRAND | B25: 2029–2040 | C25: =+C24+1 -> 2043 | D25: GENERIC | E25: 0.083 | F25: 241.7 | G25: -19.3 | H25: 0 | I25: -72.5 | J25: =+F25+SUM(G25:I25) -> 149.9 | K25: 0 | L25: =-J25*0.21 -> -31.479 | M25: =+J25+L25 -> 118.421 | N25: 0.5 | O25: =+M25*N25 -> 59.2105 | P25: 316.1 | R25: 2043 | S25: GENERIC | T25: 59.21 | U25: 316.1
A26: ■ GENERIC | B26: 2041–2045 | C26: =+C25+1 -> 2044 | D26: GENERIC | E26: 0.06 | F26: 131 | G26: -10.5 | H26: 0 | I26: -39.3 | J26: =+F26+SUM(G26:I26) -> 81.2 | K26: 0 | L26: =-J26*0.21 -> -17.052 | M26: =+J26+L26 -> 64.148 | N26: 0.5 | O26: =+M26*N26 -> 32.074 | P26: 319.3 | R26: 2044 | S26: GENERIC | T26: 32.07 | U26: 319.3
C27: =+C26+1 -> 2045 | D27: GENERIC | E27: 0.038 | F27: 52.5 | G27: -4.2 | H27: 0 | I27: -15.7 | J27: =+F27+SUM(G27:I27) -> 32.6 | K27: 0 | L27: =-J27*0.21 -> -6.846 | M27: =+J27+L27 -> 25.754 | N27: 0.5 | O27: =+M27*N27 -> 12.877 | P27: 320.4 | R27: 2045 | S27: GENERIC | T27: 12.88 | U27: 320.4
